FF
======================================================================
FAIL: test_global_function (test_hiker.TestHiker)
----------------------------------------------------------------------
Traceback (most recent call last):
  File "/sandbox/test_hiker.py", line 8, in test_global_function
    self.assertEqual(42, global_answer())
AssertionError: 42 != 54

======================================================================
FAIL: test_instance_method (test_hiker.TestHiker)
----------------------------------------------------------------------
Traceback (most recent call last):
  File "/sandbox/test_hiker.py", line 11, in test_instance_method
    self.assertEqual(42, Hiker().instance_answer())
AssertionError: 42 != 54

----------------------------------------------------------------------
Ran 2 tests in 0.000s

FAILED (failures=2)
